<?xml version="1.0" ?>
<!-- =================================================================================== -->
<!-- |    This document was autogenerated by xacro from robot.xacro                    | -->
<!-- |    EDITING THIS FILE BY HAND IS NOT RECOMMENDED                                 | -->
<!-- =================================================================================== -->
<robot name="hector_description">
  <material name="black">
    <color rgba="0.0 0.0 0.0 1.0"/>
  </material>
  <material name="blue">
    <color rgba="0.0 0.0 0.8 1.0"/>
  </material>
  <material name="green">
    <color rgba="0.0 0.8 0.0 1.0"/>
  </material>
  <material name="grey">
    <color rgba="0.2 0.2 0.2 1.0"/>
  </material>
  <material name="silver">
    <color rgba="0.9137254901960784 0.9137254901960784 0.8470588235294118 1.0"/>
  </material>
  <material name="orange">
    <color rgba="1.0 0.4235294117647059 0.0392156862745098 1.0"/>
  </material>
  <material name="brown">
    <color rgba="0.8705882352941177 0.8117647058823529 0.7647058823529411 1.0"/>
  </material>
  <material name="red">
    <color rgba="0.8 0.0 0.0 1.0"/>
  </material>
  <material name="white">
    <color rgba="1.0 1.0 1.0 1.0"/>
  </material>

  <link name="base">
    <visual>
      <origin rpy="0 0 0" xyz="0 0 0"/>
      <geometry>
        <box size="0.001 0.001 0.001"/>
      </geometry>
    </visual>
  </link>

  <joint name="floating_base" type="fixed">
    <origin rpy="0 0 0" xyz="0 0 0"/>
    <parent link="base"/>
    <child link="trunk"/>
  </joint>

  <link name="trunk">
    <visual>
      <origin rpy="0 0 0" xyz="0 0 0"/>
      <geometry>
        <mesh filename="package://hector_description/meshes/body.STL" scale="1 1 1"/>
      </geometry>
      <material name="black"/>
    </visual>
    <collision>
      <origin rpy="0 0 0" xyz="0 0 0"/>
      <geometry>
        <box size="0.125 0.19 0.248"/>
      </geometry>
    </collision>
    <inertial>
      <origin rpy="0 0 0" xyz="0.0 0.0 0.0"/>
      <mass value="4.87"/>
      <inertia ixx="0.052" ixy="0.0" ixz="0.0" iyy="0.0441" iyz="0.0" izz="0.0184"/>
    </inertial>
  </link>

  <joint name="imu_joint" type="fixed">
    <parent link="trunk"/>
    <child link="imu_link"/>
    <origin rpy="0 0 0" xyz="0 0 0"/>
  </joint>

  <link name="imu_link">
    <inertial>
      <mass value="0.001"/>
      <origin rpy="0 0 0" xyz="0 0 0"/>
      <inertia ixx="0.0001" ixy="0" ixz="0" iyy="0.0001" iyz="0" izz="0.0001"/>
    </inertial>
    <visual>
      <origin rpy="0 0 0" xyz="0 0 0"/>
      <geometry>
        <box size="0.001 0.001 0.001"/>
      </geometry>
      <material name="black"/>
    </visual>
    <collision>
      <origin rpy="0 0 0" xyz="0 0 0"/>
      <geometry>
        <box size=".001 .001 .001"/>
      </geometry>
    </collision>
  </link>

  <joint name="L_hip_joint" type="revolute">
    <origin rpy="0 0 0" xyz="0.0 0.047 -0.1265"/>
    <parent link="trunk"/>
    <child link="L_hip"/>
    <axis xyz="0 0 1"/>
    <dynamics damping="0.1" friction="0.0"/>
    <limit effort="33.5" lower="-0.7853981633974483" upper="0.7853981633974483" velocity="21"/>
  </joint>

  <link name="L_hip">
    <visual>
      <origin rpy="0 0 0" xyz="0 0 0"/>
      <geometry>
        <mesh filename="package://hector_description/meshes/L_hip1.STL" scale="1 1 1"/>
      </geometry>
      <material name="black"/>
    </visual>
    <collision>
      <origin rpy="0 0 0" xyz="0.015 0.0 -0.002"/>
      <geometry>
        <box size="0.0001 0.0001 0.0001"/>
      </geometry>
    </collision>
    <inertial>
      <origin rpy="0 0 0" xyz="0.025109 -0.002292 -0.024732"/>
      <mass value="0.224"/>
      <inertia ixx="2.104e-06" ixy="0.0" ixz="0.0" iyy="5.354e-06" iyz="0.0" izz="7.416e-06"/>
    </inertial>
  </link>

  <!--this link is only for motor mass&colllision-->
  <joint name="L_hip_trans_joint" type="fixed">
    <origin rpy="0 0 0" xyz="0.079 0.015 -0.0705"/>
    <parent link="L_hip"/>
    <child link="L_hip_trans"/>
  </joint>

  <link name="L_hip_trans">
    <collision>
      <origin rpy="0 1.5707963267948966 0" xyz="0 0 0"/>
      <geometry>
        <cylinder length="0.04" radius="0.045"/>
      </geometry>
    </collision>
    <inertial>
      <origin rpy="0 0 0" xyz="0 0 0"/>
      <mass value="0.605"/>
      <inertia ixx="0.00048" ixy="0.0" ixz="0.0" iyy="0.00048" iyz="0.0" izz="0.00071"/>
    </inertial>
  </link>

  <joint name="L_hip2_joint" type="revolute">
    <origin rpy="0 0 0" xyz="0.0465 0.015 -0.0705"/>
    <parent link="L_hip"/>
    <child link="L_hip2"/>
    <axis xyz="1 0 0"/>
    <dynamics damping="0.1" friction="0.0"/>
    <limit effort="33.5" lower="-0.7853981633974483" upper="0.7853981633974483" velocity="21"/>
  </joint>

  <link name="L_hip2">
    <visual>
      <origin rpy="0 0 0" xyz="0 0 0"/>
      <geometry>
        <mesh filename="package://hector_description/meshes/L_hip2.STL" scale="1 1 1"/>
      </geometry>
      <material name="black"/>
    </visual>
    <collision>
      <origin rpy="0 0 0" xyz="-0.1 0 0"/>
      <geometry>
        <box size="1e-05 1e-05 1e-05"/>
      </geometry>
    </collision>
    <inertial>
      <origin rpy="0 0 0" xyz="-0.033217 -0.010231 0"/>
      <mass value="0.095"/>
      <inertia ixx="5.1083e-05" ixy="0.0" ixz="0.0" iyy="1.39825e-05" iyz="0.0" izz="9.3473e-05"/>
    </inertial>
  </link>

  <!--this link is only for collision-->
  <joint name="L_hip2_trans_joint" type="fixed">
    <origin rpy="0 0 0" xyz="-0.06 -0.015 0.0"/>
    <parent link="L_hip2"/>
    <child link="L_hip2_trans"/>
  </joint>

  <link name="L_hip2_trans">
    <collision>
      <origin rpy="-1.5707963267948966 0 0" xyz="0 0 0"/>
      <geometry>
        <cylinder length="0.04" radius="0.045"/>
      </geometry>
    </collision>
    <inertial>
      <origin rpy="-1.5707963267948966 0 0" xyz="0 0 0"/>
      <mass value="0.605"/>
      <inertia ixx="0.00048" ixy="0.0" ixz="0.0" iyy="0.00048" iyz="0.0" izz="0.00071"/>
    </inertial>
  </link>

  <joint name="L_thigh_joint" type="revolute">
    <origin rpy="0 0.7853981633974483 0" xyz="-0.06 0.018 0"/>
    <parent link="L_hip2"/>
    <child link="L_thigh"/>
    <axis xyz="0 1 0"/>
    <joint_properties damping="0.1" friction="0.0"/>
    <!-- <limit effort="${thigh_torque_max}" velocity="${thigh_velocity_max}"/> -->
    <limit effort="33.5" lower="-1.7453292519943295" upper="1.7453292519943295" velocity="21"/>
  </joint>

  <link name="L_thigh">
    <visual>
      <origin rpy="0 0 0" xyz="0 0 0"/>
      <geometry>
        <mesh filename="package://hector_description/meshes/L_thigh.STL" scale="1 1 1"/>
      </geometry>
      <material name="grey"/>
    </visual>
    <collision>
      <origin rpy="0 0 0" xyz="0.0 0.0175 -0.09"/>
      <geometry>
        <box size="0.06 0.035 0.18"/>
      </geometry>
    </collision>
    <inertial>
      <origin rpy="0 0 0" xyz="-0.00034 0.01626 -0.09817"/>
      <mass value="0.321"/>
      <inertia ixx="0.00238" ixy="0.0" ixz="0.0" iyy="0.00249" iyz="0.0" izz="0.00029"/>
    </inertial>
  </link>

  <!--this link is only for collision-->
  <joint name="L_thigh1_trans_joint" type="fixed">
    <origin rpy="0 0 0" xyz="0.0 0.037 0.0"/>
    <parent link="L_thigh"/>
    <child link="L_thigh1_trans"/>
  </joint>

  <link name="L_thigh1_trans">
    <collision>
      <origin rpy="-1.5707963267948966 0 0" xyz="0 0 0"/>
      <geometry>
        <cylinder length="0.04" radius="0.045"/>
      </geometry>
    </collision>
    <inertial>
      <origin rpy="-1.5707963267948966 0 0" xyz="0 0 0"/>
      <mass value="0.605"/>
      <inertia ixx="0.00048" ixy="0.0" ixz="0.0" iyy="0.00048" iyz="0.0" izz="0.00071"/>
    </inertial>
  </link>

  <!--this link is only for collision-->
  <joint name="L_thigh2_trans_joint" type="fixed">
    <origin rpy="0 0 0" xyz="0.0 0.037 -0.095"/>
    <parent link="L_thigh"/>
    <child link="L_thigh2_trans"/>
  </joint>

  <link name="L_thigh2_trans">
    <collision>
      <origin rpy="-1.5707963267948966 0 0" xyz="0 0 0"/>
      <geometry>
        <cylinder length="0.04" radius="0.045"/>
      </geometry>
    </collision>
    <inertial>
      <origin rpy="-1.5707963267948966 0 0" xyz="0 0 0"/>
      <mass value="0.605"/>
      <inertia ixx="0.00048" ixy="0.0" ixz="0.0" iyy="0.00048" iyz="0.0" izz="0.00071"/>
    </inertial>
  </link>

  <joint name="L_calf_joint" type="revolute">
    <origin rpy="0 -1.5707963267948966 0" xyz="0.0 0.018 -0.22"/>
    <parent link="L_thigh"/>
    <child link="L_calf"/>
    <axis xyz="0 1 0"/>
    <joint_properties damping="0.1" friction="0.0"/>
    <limit effort="67" lower="-1.7453292519943295" upper="1.7453292519943295" velocity="14"/>
  </joint>

  <link name="L_calf">
    <visual>
      <origin rpy="0 0 0" xyz="0 0 0"/>
      <geometry>
        <mesh filename="package://hector_description/meshes/calf.STL" scale="1 1 1"/>
      </geometry>
      <material name="grey"/>
    </visual>
    <collision>
      <origin rpy="0 0 0" xyz="0.0 0.0 -0.11"/>
      <geometry>
        <cylinder length="0.18" radius="0.015"/>
      </geometry>
    </collision>
    <inertial>
      <origin rpy="0 0 0" xyz="0.0 0.0 -0.089"/>
      <mass value="0.177"/>
      <inertia ixx="0.00113" ixy="0.0" ixz="0.0" iyy="0.00114" iyz="0.0" izz="4e-05"/>
    </inertial>
  </link>

  <joint name="L_toe_joint" type="revolute">
    <origin rpy="0 0.7853981633974483 0" xyz="0.0 0.0 -0.22"/>
    <parent link="L_calf"/>
    <child link="L_toe"/>
    <axis xyz="0 1 0"/>
    <joint_properties damping="0.1" friction="0.0"/>
    <limit effort="33.5" lower="-1.7453292519943295" upper="1.7453292519943295" velocity="21"/>
  </joint>

  <link name="L_toe">
    <visual>
      <origin rpy="0 0 0" xyz="0 0 0"/>
      <geometry>
        <mesh filename="package://hector_description/meshes/L_foot.STL" scale="1 1 1"/>
      </geometry>
      <material name="black"/>
    </visual>
    <collision>
      <origin rpy="0 0 0" xyz="0.01 0.0 -0.02"/>
      <geometry>
        <box size="0.15 0.02 0.04"/>
      </geometry>
    </collision>
    <inertial>
      <origin rpy="0 0 0" xyz="0.00622 0.00096 -0.01341"/>
      <mass value="0.117"/>
      <inertia ixx="6e-05" ixy="0.0" ixz="0.0" iyy="0.00016" iyz="0.0" izz="0.00016"/>
    </inertial>
  </link>

  <transmission name="L_hip_tran">
    <type>transmission_interface/SimpleTransmission</type>
    <joint name="L_hip_joint">
      <hardwareInterface>hardware_interface/EffortJointInterface</hardwareInterface>
    </joint>
    <actuator name="L_hip_motor">
      <hardwareInterface>hardware_interface/EffortJointInterface</hardwareInterface>
      <mechanicalReduction>1</mechanicalReduction>
    </actuator>
  </transmission>

  <transmission name="L_hip2_tran">
    <type>transmission_interface/SimpleTransmission</type>
    <joint name="L_hip2_joint">
      <hardwareInterface>hardware_interface/EffortJointInterface</hardwareInterface>
    </joint>
    <actuator name="L_hip2_motor">
      <hardwareInterface>hardware_interface/EffortJointInterface</hardwareInterface>
      <mechanicalReduction>1</mechanicalReduction>
    </actuator>
  </transmission>

  <transmission name="L_thigh_tran">
    <type>transmission_interface/SimpleTransmission</type>
    <joint name="L_thigh_joint">
      <hardwareInterface>hardware_interface/EffortJointInterface</hardwareInterface>
    </joint>
    <actuator name="L_thigh_motor">
      <hardwareInterface>hardware_interface/EffortJointInterface</hardwareInterface>
      <mechanicalReduction>1</mechanicalReduction>
    </actuator>
  </transmission>

  <transmission name="L_calf_tran">
    <type>transmission_interface/SimpleTransmission</type>
    <joint name="L_calf_joint">
      <hardwareInterface>hardware_interface/EffortJointInterface</hardwareInterface>
    </joint>
    <actuator name="L_calf_motor">
      <hardwareInterface>hardware_interface/EffortJointInterface</hardwareInterface>
      <mechanicalReduction>1</mechanicalReduction>
    </actuator>
  </transmission>

  <transmission name="L_toe_tran">
    <type>transmission_interface/SimpleTransmission</type>
    <joint name="L_toe_joint">
      <hardwareInterface>hardware_interface/EffortJointInterface</hardwareInterface>
    </joint>
    <actuator name="L_toe_motor">
      <hardwareInterface>hardware_interface/EffortJointInterface</hardwareInterface>
      <mechanicalReduction>1</mechanicalReduction>
    </actuator>
  </transmission>

  <!-- Right leg -->

  <joint name="R_hip_joint" type="revolute">
    <origin rpy="0 0 0" xyz="0.0 -0.047 -0.1265"/>
    <parent link="trunk"/>
    <child link="R_hip"/>
    <axis xyz="0 0 1"/>
    <dynamics damping="0.1" friction="0.0"/>
    <limit effort="33.5" lower="-0.7853981633974483" upper="0.7853981633974483" velocity="21"/>
  </joint>

  <link name="R_hip">
    <visual>
      <origin rpy="0 0 0" xyz="0 0 0"/>
      <geometry>
        <mesh filename="package://hector_description/meshes/R_hip1.STL" scale="1 1 1"/>
      </geometry>
      <material name="black"/>
    </visual>
    <collision>
      <origin rpy="0 0 0" xyz="0.015 0.0 -0.002"/>
      <geometry>
        <box size="0.0001 0.0001 0.0001"/>
      </geometry>
    </collision>
    <inertial>
      <origin rpy="0 0 0" xyz="0.025109 -0.002292 -0.024732"/>
      <mass value="0.224"/>
      <inertia ixx="2.104e-06" ixy="0.0" ixz="0.0" iyy="5.354e-06" iyz="0.0" izz="7.416e-06"/>
    </inertial>
  </link>

  <!--this link is only for motor mass&colllision-->
  <joint name="R_hip_trans_joint" type="fixed">
    <origin rpy="0 0 0" xyz="0.079 -0.015 -0.0705"/>
    <parent link="R_hip"/>
    <child link="R_hip_trans"/>
  </joint>
  <link name="R_hip_trans">
    <collision>
      <origin rpy="0 1.5707963267948966 0" xyz="0 0 0"/>
      <geometry>
        <cylinder length="0.04" radius="0.045"/>
      </geometry>
    </collision>
    <inertial>
      <origin rpy="0 0 0" xyz="0 0 0"/>
      <mass value="0.605"/>
      <inertia ixx="0.00048" ixy="0.0" ixz="0.0" iyy="0.00048" iyz="0.0" izz="0.00071"/>
    </inertial>
  </link>

  <joint name="R_hip2_joint" type="revolute">
    <origin rpy="0 0 0" xyz="0.0465 -0.015 -0.0705"/>
    <parent link="R_hip"/>
    <child link="R_hip2"/>
    <axis xyz="1 0 0"/>
    <dynamics damping="0.1" friction="0.0"/>
    <limit effort="33.5" lower="-0.7853981633974483" upper="0.7853981633974483" velocity="21"/>
  </joint>

  <link name="R_hip2">
    <visual>
      <origin rpy="0 0 0" xyz="0 0 0"/>
      <geometry>
        <mesh filename="package://hector_description/meshes/R_hip2.STL" scale="1 1 1"/>
      </geometry>
      <material name="black"/>
    </visual>
    <collision>
      <origin rpy="0 0 0" xyz="-0.1 0 0"/>
      <geometry>
        <box size="1e-05 1e-05 1e-05"/>
      </geometry>
    </collision>
    <inertial>
      <origin rpy="0 0 0" xyz="-0.033217 -0.010231 0"/>
      <mass value="0.095"/>
      <inertia ixx="5.1083e-05" ixy="0.0" ixz="0.0" iyy="1.39825e-05" iyz="0.0" izz="9.3473e-05"/>
    </inertial>
  </link>

  <!--this link is only for collision-->
  <joint name="R_hip2_trans_joint" type="fixed">
    <origin rpy="0 0 0" xyz="-0.06 0.015 0.0"/>
    <parent link="R_hip2"/>
    <child link="R_hip2_trans"/>
  </joint>

  <link name="R_hip2_trans">
    <collision>
      <origin rpy="-1.5707963267948966 0 0" xyz="0 0 0"/>
      <geometry>
        <cylinder length="0.04" radius="0.045"/>
      </geometry>
    </collision>
    <inertial>
      <origin rpy="-1.5707963267948966 0 0" xyz="0 0 0"/>
      <mass value="0.605"/>
      <inertia ixx="0.00048" ixy="0.0" ixz="0.0" iyy="0.00048" iyz="0.0" izz="0.00071"/>
    </inertial>
  </link>

  <joint name="R_thigh_joint" type="revolute">
    <origin rpy="0 0.7853981633974483 0" xyz="-0.06 -0.018 0"/>
    <parent link="R_hip2"/>
    <child link="R_thigh"/>
    <axis xyz="0 1 0"/>
    <joint_properties damping="0.1" friction="0.0"/>
    <!-- <limit effort="${thigh_torque_max}" velocity="${thigh_velocity_max}"/> -->
    <limit effort="33.5" lower="-1.7453292519943295" upper="1.7453292519943295" velocity="21"/>
  </joint>

  <link name="R_thigh">
    <visual>
      <origin rpy="0 0 0" xyz="0 0 0"/>
      <geometry>
        <mesh filename="package://hector_description/meshes/R_thigh.STL" scale="1 1 1"/>
      </geometry>
      <material name="grey"/>
    </visual>
    <collision>
      <origin rpy="0 0 0" xyz="0.0 -0.0175 -0.09"/>
      <geometry>
        <box size="0.06 0.035 0.18"/>
      </geometry>
    </collision>
    <inertial>
      <origin rpy="0 0 0" xyz="-0.00034 -0.01626 -0.09817"/>
      <mass value="0.321"/>
      <inertia ixx="0.00238" ixy="0.0" ixz="0.0" iyy="0.00249" iyz="0.0" izz="0.00029"/>
    </inertial>
  </link>

  <!--this link is only for collision-->
  <joint name="R_thigh1_trans_joint" type="fixed">
    <origin rpy="0 0 0" xyz="0.0 -0.037 0.0"/>
    <parent link="R_thigh"/>
    <child link="R_thigh1_trans"/>
  </joint>
  <link name="R_thigh1_trans">
    <collision>
      <origin rpy="-1.5707963267948966 0 0" xyz="0 0 0"/>
      <geometry>
        <cylinder length="0.04" radius="0.045"/>
      </geometry>
    </collision>
    <inertial>
      <origin rpy="-1.5707963267948966 0 0" xyz="0 0 0"/>
      <mass value="0.605"/>
      <inertia ixx="0.00048" ixy="0.0" ixz="0.0" iyy="0.00048" iyz="0.0" izz="0.00071"/>
    </inertial>
  </link>

  <!--this link is only for collision-->
  <joint name="R_thigh2_trans_joint" type="fixed">
    <origin rpy="0 0 0" xyz="0.0 -0.037 -0.095"/>
    <parent link="R_thigh"/>
    <child link="R_thigh2_trans"/>
  </joint>
  <link name="R_thigh2_trans">
    <collision>
      <origin rpy="-1.5707963267948966 0 0" xyz="0 0 0"/>
      <geometry>
        <cylinder length="0.04" radius="0.045"/>
      </geometry>
    </collision>
    <inertial>
      <origin rpy="-1.5707963267948966 0 0" xyz="0 0 0"/>
      <mass value="0.605"/>
      <inertia ixx="0.00048" ixy="0.0" ixz="0.0" iyy="0.00048" iyz="0.0" izz="0.00071"/>
    </inertial>
  </link>

  <joint name="R_calf_joint" type="revolute">
    <origin rpy="0 -1.5707963267948966 0" xyz="0.0 -0.018 -0.22"/>
    <parent link="R_thigh"/>
    <child link="R_calf"/>
    <axis xyz="0 1 0"/>
    <joint_properties damping="0.1" friction="0.0"/>
    <limit effort="67" lower="-1.7453292519943295" upper="1.7453292519943295" velocity="14"/>
  </joint>

  <link name="R_calf">
    <visual>
      <origin rpy="0 0 0" xyz="0 0 0"/>
      <geometry>
        <mesh filename="package://hector_description/meshes/calf.STL" scale="1 1 1"/>
      </geometry>
      <material name="grey"/>
    </visual>
    <collision>
      <origin rpy="0 0 0" xyz="0.0 0.0 -0.11"/>
      <geometry>
        <cylinder length="0.18" radius="0.015"/>
      </geometry>
    </collision>
    <inertial>
      <origin rpy="0 0 0" xyz="0.0 -0.0 -0.089"/>
      <mass value="0.177"/>
      <inertia ixx="0.00113" ixy="0.0" ixz="0.0" iyy="0.00114" iyz="0.0" izz="4e-05"/>
    </inertial>
  </link>

  <joint name="R_toe_joint" type="revolute">
    <origin rpy="0 0.7853981633974483 0" xyz="0.0 0.0 -0.22"/>
    <parent link="R_calf"/>
    <child link="R_toe"/>
    <axis xyz="0 1 0"/>
    <joint_properties damping="0.1" friction="0.0"/>
    <limit effort="33.5" lower="-1.7453292519943295" upper="1.7453292519943295" velocity="21"/>
  </joint>

  <link name="R_toe">
    <visual>
      <origin rpy="0 0 0" xyz="0 0 0"/>
      <geometry>
        <mesh filename="package://hector_description/meshes/R_foot.STL" scale="1 1 1"/>
      </geometry>
      <material name="black"/>
    </visual>
    <collision>
      <origin rpy="0 0 0" xyz="0.01 0.0 -0.02"/>
      <geometry>
        <box size="0.15 0.02 0.04"/>
      </geometry>
    </collision>
    <inertial>
      <origin rpy="0 0 0" xyz="0.00622 -0.00096 -0.01341"/>
      <mass value="0.117"/>
      <inertia ixx="6e-05" ixy="0.0" ixz="0.0" iyy="0.00016" iyz="0.0" izz="0.00016"/>
    </inertial>
  </link>

  <transmission name="R_hip_tran">
    <type>transmission_interface/SimpleTransmission</type>
    <joint name="R_hip_joint">
      <hardwareInterface>hardware_interface/EffortJointInterface</hardwareInterface>
    </joint>
    <actuator name="R_hip_motor">
      <hardwareInterface>hardware_interface/EffortJointInterface</hardwareInterface>
      <mechanicalReduction>1</mechanicalReduction>
    </actuator>
  </transmission>

  <transmission name="R_hip2_tran">
    <type>transmission_interface/SimpleTransmission</type>
    <joint name="R_hip2_joint">
      <hardwareInterface>hardware_interface/EffortJointInterface</hardwareInterface>
    </joint>
    <actuator name="R_hip2_motor">
      <hardwareInterface>hardware_interface/EffortJointInterface</hardwareInterface>
      <mechanicalReduction>1</mechanicalReduction>
    </actuator>
  </transmission>

  <transmission name="R_thigh_tran">
    <type>transmission_interface/SimpleTransmission</type>
    <joint name="R_thigh_joint">
      <hardwareInterface>hardware_interface/EffortJointInterface</hardwareInterface>
    </joint>
    <actuator name="R_thigh_motor">
      <hardwareInterface>hardware_interface/EffortJointInterface</hardwareInterface>
      <mechanicalReduction>1</mechanicalReduction>
    </actuator>
  </transmission>

  <transmission name="R_calf_tran">
    <type>transmission_interface/SimpleTransmission</type>
    <joint name="R_calf_joint">
      <hardwareInterface>hardware_interface/EffortJointInterface</hardwareInterface>
    </joint>
    <actuator name="R_calf_motor">
      <hardwareInterface>hardware_interface/EffortJointInterface</hardwareInterface>
      <mechanicalReduction>1</mechanicalReduction>
    </actuator>
  </transmission>
  
  <transmission name="R_toe_tran">
    <type>transmission_interface/SimpleTransmission</type>
    <joint name="R_toe_joint">
      <hardwareInterface>hardware_interface/EffortJointInterface</hardwareInterface>
    </joint>
    <actuator name="R_toe_motor">
      <hardwareInterface>hardware_interface/EffortJointInterface</hardwareInterface>
      <mechanicalReduction>1</mechanicalReduction>
    </actuator>
  </transmission>
</robot>
